####  Runnable的缺陷

◆不能返回一个返回值

◆也不能抛出 checked Exception（代码演示）

```java
Runnable runnable = () -> {
    try {
        throw new Exception();
    } catch (Exception e) {
        e.printStackTrace();
    }
};
```

◆为什么有这样的缺陷？

◆ Runnable为什么设计成这样？

◆针对于无法抛岀检査后异常这个缺陷的补救措施



`Callable`接口

```java
@FunctionalInterface
public interface Callable<V> {
    /**
     * Computes a result, or throws an exception if unable to do so.
     *
     * @return computed result
     * @throws Exception if unable to compute a result
     */
    V call() throws Exception;
}
```

#### **Callable和 Future的关系**

◆我们可以用 `Future.get`来获取 `Callable`接口返回的执行结果还可以通过 `Future.isDone`来判断任务是否已经执行完了，以及取消这个任务，限时获取任务的结果等

◆在`call()`未执行完毕之前，调用`get()`的线程（假定此时是主线程）会被阻塞，直到`call()`方法返回了结果后，此时`future. get()`才会得到该结果，然后主线程才会切换到`runnable`状态

◆所以 `Future`是一个存储器，它存储了`call()`这个任务的结果，而这个任务的执行时间是无法提前确定的，因为这完全取决于`call()`方法执行的情况



`Future`的几个方法: 

```java
boolean cancel(boolean mayInterruptIfRunning);
boolean isCancelled();
boolean isDone();
V get() throws InterruptedException, ExecutionException;
V get(long timeout, TimeUnit unit)throws InterruptedException, ExecutionException, TimeoutException;
```



**`get()`方法:获取结果**

`get`方法的行为取决于 `Callable`任务的状态，只有以下这5种情况

1. 任务正常完成:`get`方法会立刻返回结果

2. 任务尚未完成（任务还没开始或进行中）:get将阻塞并直到任务完成。

3. 任务执行过程中抛出 `Exception`:`get`方法会抛出`ExecutionException`:这里的抛出异常，是`call()`执行时产生的那个异常，看到这个异常类型是`java.util.concurrent. ExecutionException`。不论`call`执行时抛出的异常类型是什么，最后`get`方法抛出的异常类型都是ExecutionException

4. 任务被取消:`get`方法会抛出 `CancellationException`

5. 任务超时:`get`方法有一个重载方法，是传入一个延迟时间的，如果时间到了还没有获得结果，`get`方法就会抛出`TimeoutException`。



**get(long timeout, TimeUnit unit):有超时的获取**

◆超时的需求很常见

◆用 `get(long timeout, TimeUnit unit)`方法时，如果`call`在规定时间内完成了任务，那么就会正常获取到返回值;而如果再指定时间内没有计算出结果，那么就会抛出`TimeoutException`

◆超时不获取，任务需取消



#### 线程池的 Submit方法返回 Future对象

首先，我们要给线程池提交我们的任务，提交时线程池会立刻返回给我们一个空的 Future容器。当线程的任务一旦执行完毕，也就是当我们可以获取结果的时候，线程池便会把该结果填入到之前给我们的那个 Future中去（而不是创建一个新的Future），我们此时便可以从该 Future中获得任务执行的结果。

返回单个Future：

```java
public static void main(String[] args) throws ExecutionException, InterruptedException {
    ExecutorService service = Executors.newFixedThreadPool(10);
    Future<Integer> future = service.submit(new CallableTask());
    Integer r = future.get();
    System.out.println(r);
    service.shutdown();
}

static class CallableTask implements Callable<Integer> {
    @Override
    public Integer call() throws Exception {
        Thread.sleep(10000L);
        return 13;
    }
}
```

多个Future：

```java
public static void main(String[] args) throws ExecutionException, InterruptedException {
    ExecutorService service = Executors.newFixedThreadPool(10);
    List<Future<Integer>> futureList = new ArrayList<>();
    for (int i = 0; i < 20; i++) {
        Future<Integer> future = service.submit(new CallableTask());
        futureList.add(future);
    }
    for (int i = 0; i < 20; i++) {
        Future<Integer> future = futureList.get(i);
        Integer r = future.get();
        System.out.println(r);
    }
    service.shutdown();
}
static class CallableTask implements Callable<Integer> {
    @Override
    public Integer call() throws Exception {
        Thread.sleep(1000L);
        return new Random().nextInt(100);
    }
}
```

抛出`ExecutionException`异常：

```java
public static void main(String[] args) throws ExecutionException, InterruptedException {
    ExecutorService service = Executors.newFixedThreadPool(10);
    Future<Integer> future = service.submit(new CallableTask());
    Integer r = future.get();
    System.out.println(r);
    service.shutdown();
}
static class CallableTask implements Callable<Integer> {
    @Override
    public Integer call() throws Exception {
        throw new RuntimeException(Thread.currentThread().getName() + "出现异常了");
    }
}
```

```java
Exception in thread "main" java.util.concurrent.ExecutionException: java.lang.RuntimeException: pool-1-thread-1出现异常了
	at java.base/java.util.concurrent.FutureTask.report(FutureTask.java:122)
	at java.base/java.util.concurrent.FutureTask.get(FutureTask.java:191)
	at com.zeny.threadstudy.GetException.main(GetException.java:16)
Caused by: java.lang.RuntimeException: pool-1-thread-1出现异常了
	at com.zeny.threadstudy.GetException$CallableTask.call(GetException.java:23)
	at com.zeny.threadstudy.GetException$CallableTask.call(GetException.java:20)
	at java.base/java.util.concurrent.FutureTask.run(FutureTask.java:264)
	at java.base/java.util.concurrent.ThreadPoolExecutor.runWorker(ThreadPoolExecutor.java:1128)
	at java.base/java.util.concurrent.ThreadPoolExecutor$Worker.run(ThreadPoolExecutor.java:628)
	at java.base/java.lang.Thread.run(Thread.java:834)

```



**`cancel`方法:取消任务的执行**

1. 如果这个任务还没有开始执行，那么这种情况最简单，任务会被正常的取消，未来也不会被执行，方法返回`true`。

2. 如果任务已完成，或者已取消:那么 `cancel`方法会执行失败方法返回 `False`。

3. 如果这个任务已经开始执行了，那么这个取消方法将不会直接取消该任务，而是会根据我们填的参数 `mayInterruptifRunning`做判断。

   

**Future.cancel(true)适用于**

1. 任务能够处理 Interrupt

**Future.cancel(false)仅用于避免启动尚未启动的任务，适用于**

1. 未能处理 `Interrupt`的任务

2. 不清楚任务是否支持取消

3. 需要等待已经开始的任务执行完成



用 `FutureTask`来创建 `Future`

![image-20211226170648551](https://gitee.com/JKcoding/imgs/raw/master/img/202112261706347.png)

◆所以它既可以作为 `Runnable`被线程执行，又可以作为 `Future`得到 `Callable`的返回值

◆把 `Callable`实例当作参数，生成 `FutureTask`的对象，然后把这个对象当作一个 `Runnable`对象，用线程池或另起线程去执行这个 `Runnable`对象，最后通过 `FutureTask`获取刚才执行的结果

```java
public static void main(String[] args) {
    Task task = new Task();
    FutureTask<Integer> futureTask = new FutureTask<>(task);
    new Thread(futureTask).start();
    try {
        Integer sum = futureTask.get();
        System.out.println("task : " + sum);
    } catch (InterruptedException e) {
        e.printStackTrace();
    } catch (ExecutionException e) {
        e.printStackTrace();
    }
}

static class Task implements Callable<Integer> {

    @Override
    public Integer call() throws Exception {
        System.out.println("子线程正在计算");
        Thread.sleep(3000);
        int sum = 0;
        for (int i = 0; i < 100; i++) {
            sum += i;
        }
        return sum;
    }
}
```



#### Future的注意点

◆当`for`循环批量获取 `future`的结果时，容易发生-部分线程很慢的情况，`get`方法调用时应使用 `timeout`限制

◆ Future的生命周期不能后退

​	◆生命周期只能前进，不能后退。就和线程池的生命周期一样，一旦完全完成了任务，它就永久停在了“已完成”的状态，不能重头再来

